Workbook

Sheet FIFA World cup 2026
A1: "Av alle uviktige ting i verden er fotball den aller viktigste" (pave Johannes Paul II)
A2: Gruppene:
A3: A: | B3: B: | C3: C: | E3: D: | F3: E: | K3: F: | N3: G: | S3: H: | Y3: I: | AC3: J: | AG3: K: | AK3: L:
A4: Mexico | B4: Canada | C4: Brasil | E4: USA | F4: Tyskland | K4: Nederland | N4: Belgia | S4: Spania | Y4: Frankrike | AC4: Argentina | AG4: Portugal | AK4: England
A5: Sør-Afrika | B5: Qatar | C5: Marokko | E5: Tyrkia | F5: Elfenbenskysten | K5: Japan | N5: Iran | S5: Saudi-Arabia | Y5: Norge | AC5: Østerrike | AG5: Usbekistan | AK5: Kroatia
A6: Sør-Korea | B6: Bosnia-Herceg. | C6: Haiti | E6: Australia | F6: Ecuador | K6: Sverige | N6: Egypt | S6: Uruguay | Y6: Irak | AC6: Jordan | AG6: Colombia | AK6: Panama
A7: Tsjekkia | B7: Sveits | C7: Skottland | E7: Paraguay | F7: Curacao | K7: Tunisia | N7: New Zealand | S7: Kapp Verde | Y7: Senegal | AC7: Algerie | AG7: DR Kongo | AK7: Ghana
A9: Gruppespillet:
A10: (Tipp sluttresultat i kampene. Rett resultat - H/U/B - gir 1 poeng, rett målscore gir 1 poeng)
A11: Gruppe A: Torsdag 11.06.2026 21:00 Mexico - Sør-Afrika | G11: -
A12: Gruppe C: Søndag 14.06.2026 00:00 Brasil - Marokko | G12: -
A13: Gruppe H: Mandag 15.06.2026 18:00 Spania - Kapp Verde | G13: -
A14: Gruppe J: Tirsdag 17.06.2026 03:00 Argentina - Algerie | G14: -
A15: Gruppe L: Onsdag 17.06.2026 22:00 England - Kroatia | G15: -
A16: Gruppe F: Lørdag 20.06.2026 19:00 Nederland - Sverige | G16: -
A17: Gruppe I: Tirsdag 23.06.2026 02:00 Norge - Senegal | G17: -
A18: Gruppe E: Torsdag 25.06.2026 22:00 Ecuador - Tyskland | G18: -
A19: Gruppe I: Fredag 26.06.2026 21:00 Norge - Frankrike | G19: -
A20: Gruppe K: Lørdag 27.06.2026 02:00 Colombia - Portugal | G20: -
A22: (Tipp sluttresultater i gruppene, 2 poeng for hvert rett svar)
A23: Hvem blir vinner i gruppe A?
A24: Hvem blir toer i gruppe B?
A25: Går 3. plass i gruppe C videre? (J/N)
A26: Hvem blir vinner i gruppe D?
A27: Hvem blir vinner i gruppe F?
A28: Hvem blir vinner i gruppe G?
A29: Hvem blir toer i gruppe I?
A30: Går 3.plass i gruppe K videre? (J/N)
A32: Norge:
A33: (2 poeng for hvert rett svar)
A34: Kommer Norge til å score 7 mål eller mer i gruppespillet? (J/N)
... A36: Kommer Norge til å møte Brasil i finalespillet? (J/N)
A37: Hvem når lengst i VM av Norge og England? (Kryss av) | I37: Norge: | K37: England: | M37: Like langt:
A38: Hvem blir Norges toppscorer? (Kryss av) | I38: Haaland: | K38: Sørloth: | M38: En annen:
A40: Finalespillet:
A41: (2 poeng for hvert rett svar)
A42: Går Sverige videre fra gruppespillet? (J/N)
A43: Hvor mange europeiske lag går til sekstendedelsfinale?
A44: Hvilke av vertsnasjonene går videre til åttendedelsfinale?
A45: Hvilke 8 land går videre til kvartfinaler? Fyll inn
...

Sheet Sammendrag
B2: ⚽ VM 2026 – Slik tippet ekspertene
B3: Sammendrag av alle 14 innleverte tips · «Digibok med venner»
B5: "Av alle uviktige ting i verden er fotball den aller viktigste" – pave Johannes Paul II
B7: ⚽ Folkets kupong – gruppespillet
B8: Kamp | C8: Snitt-tips | D8: Folkets dom | E8: Hjemme | F8: Uavgjort | G8: Borte
B9: Mexico – Sør-Afrika | C9: =ROUND(AVERAGE(Data!B2:B15),1)&" – "&ROUND(AVERAGE(Data!C2:C15),1) -> 2.1 – 0.4 | D9: =ROUND(AVERAGE(Data!B2:B15),0)&"–"&ROUND(AVERAGE(Data!C2:C15),0) -> 2–0 | E9: =COUNTIF(Data!V2:V15,"H") -> 14 | F9: =COUNTIF(Data!V2:V15,"U") -> 0 | G9: =COUNTIF(Data!V2:V15,"B") -> 0
B10: Brasil – Marokko | C10: =ROUND(AVERAGE(Data!D2:D15),1)&" – "&ROUND(AVERAGE(Data!E2:E15),1) -> 1.5 – 0.7 | D10: =ROUND(AVERAGE(Data!D2:D15),0)&"–"&ROUND(AVERAGE(Data!E2:E15),0) -> 2–1 | E10: =COUNTIF(Data!W2:W15,"H") -> 10 | F10: =COUNTIF(Data!W2:W15,"U") -> 4 | G10: =COUNTIF(Data!W2:W15,"B") -> 0
B11: Spania – Kapp Verde | C11: =ROUND(AVERAGE(Data!F2:F15),1)&" – "&ROUND(AVERAGE(Data!G2:G15),1) -> 3.3 – 0.1 | D11: =ROUND(AVERAGE(Data!F2:F15),0)&"–"&ROUND(AVERAGE(Data!G2:G15),0) -> 3–0 | E11: =COUNTIF(Data!X2:X15,"H") -> 13 | F11: =COUNTIF(Data!X2:X15,"U") -> 1 | G11: =COUNTIF(Data!X2:X15,"B") -> 0
B12: Argentina – Algerie | C12: =ROUND(AVERAGE(Data!H2:H15),1)&" – "&ROUND(AVERAGE(Data!I2:I15),1) -> 2.1 – 0.6 | D12: =ROUND(AVERAGE(Data!H2:H15),0)&"–"&ROUND(AVERAGE(Data!I2:I15),0) -> 2–1 | E12: =COUNTIF(Data!Y2:Y15,"H") -> 13 | F12: =COUNTIF(Data!Y2:Y15,"U") -> 0 | G12: =COUNTIF(Data!Y2:Y15,"B") -> 1
B13: England – Kroatia | C13: =ROUND(AVERAGE(Data!J2:J15),1)&" – "&ROUND(AVERAGE(Data!K2:K15),1) -> 1.5 – 0.7 | D13: =ROUND(AVERAGE(Data!J2:J15),0)&"–"&ROUND(AVERAGE(Data!K2:K15),0) -> 2–1 | E13: =COUNTIF(Data!Z2:Z15,"H") -> 7 | F13: =COUNTIF(Data!Z2:Z15,"U") -> 6 | G13: =COUNTIF(Data!Z2:Z15,"B") -> 1
B14: Nederland – Sverige | C14: =ROUND(AVERAGE(Data!L2:L15),1)&" – "&ROUND(AVERAGE(Data!M2:M15),1) -> 2 – 0.6 | D14: =ROUND(AVERAGE(Data!L2:L15),0)&"–"&ROUND(AVERAGE(Data!M2:M15),0) -> 2–1 | E14: =COUNTIF(Data!AA2:AA15,"H") -> 13 | F14: =COUNTIF(Data!AA2:AA15,"U") -> 1 | G14: =COUNTIF(Data!AA2:AA15,"B") -> 0
B15: Norge – Senegal | C15: =ROUND(AVERAGE(Data!N2:N15),1)&" – "&ROUND(AVERAGE(Data!O2:O15),1) -> 1.5 – 0.9 | D15: =ROUND(AVERAGE(Data!N2:N15),0)&"–"&ROUND(AVERAGE(Data!O2:O15),0) -> 2–1 | E15: =COUNTIF(Data!AB2:AB15,"H") -> 7 | F15: =COUNTIF(Data!AB2:AB15,"U") -> 6 | G15: =COUNTIF(Data!AB2:AB15,"B") -> 1
B16: Ecuador – Tyskland | C16: =ROUND(AVERAGE(Data!P2:P15),1)&" – "&ROUND(AVERAGE(Data!Q2:Q15),1) -> 0.4 – 1.9 | D16: =ROUND(AVERAGE(Data!P2:P15),0)&"–"&ROUND(AVERAGE(Data!Q2:Q15),0) -> 0–2 | E16: =COUNTIF(Data!AC2:AC15,"H") -> 0 | F16: =COUNTIF(Data!AC2:AC15,"U") -> 0 | G16: =COUNTIF(Data!AC2:AC15,"B") -> 14
B17: Norge – Frankrike | C17: =ROUND(AVERAGE(Data!R2:R15),1)&" – "&ROUND(AVERAGE(Data!S2:S15),1) -> 1.1 – 2.3 | D17: =ROUND(AVERAGE(Data!R2:R15),0)&"–"&ROUND(AVERAGE(Data!S2:S15),0) -> 1–2 | E17: =COUNTIF(Data!AD2:AD15,"H") -> 1 | F17: =COUNTIF(Data!AD2:AD15,"U") -> 2 | G17: =COUNTIF(Data!AD2:AD15,"B") -> 11
B18: Colombia – Portugal | C18: =ROUND(AVERAGE(Data!T2:T15),1)&" – "&ROUND(AVERAGE(Data!U2:U15),1) -> 0.7 – 1.9 | D18: =ROUND(AVERAGE(Data!T2:T15),0)&"–"&ROUND(AVERAGE(Data!U2:U15),0) -> 1–2 | E18: =COUNTIF(Data!AE2:AE15,"H") -> 0 | F18: =COUNTIF(Data!AE2:AE15,"U") -> 1 | G18: =COUNTIF(Data!AE2:AE15,"B") -> 13
B20: 🏆 Gruppespørsmålene – hva tror flertallet?
B21: Spørsmål | C21: Folkets svar | D21: Oppslutning
B22: Vinner gruppe A? | C22: {=INDEX(Data!AF2:AF15,MATCH(MAX(COUNTIF(Data!AF2:AF15,Data!AF2:AF15)),COUNTIF(Data!AF2:AF15,Data!AF2:AF15),0))} -> Mexico | D22: {=MAX(COUNTIF(Data!AF2:AF15,Data!AF2:AF15))&" av 14"} -> 10 av 14
B23: Toer gruppe B? | C23: {=INDEX(Data!AG2:AG15,MATCH(MAX(COUNTIF(Data!AG2:AG15,Data!AG2:AG15)),COUNTIF(Data!AG2:AG15,Data!AG2:AG15),0))} -> Canada | D23: {=MAX(COUNTIF(Data!AG2:AG15,Data!AG2:AG15))&" av 14"} -> 6 av 14
B24: Går 3. plass i gruppe C videre? | C24: {=INDEX(Data!AH2:AH15,MATCH(MAX(COUNTIF(Data!AH2:AH15,Data!AH2:AH15)),COUNTIF(Data!AH2:AH15,Data!AH2:AH15),0))} -> Ja | D24: {=MAX(COUNTIF(Data!AH2:AH15,Data!AH2:AH15))&" av 14"} -> 9 av 14
B25: Vinner gruppe D? | C25: {=INDEX(Data!AI2:AI15,MATCH(MAX(COUNTIF(Data!AI2:AI15,Data!AI2:AI15)),COUNTIF(Data!AI2:AI15,Data!AI2:AI15),0))} -> USA | D25: {=MAX(COUNTIF(Data!AI2:AI15,Data!AI2:AI15))&" av 14"} -> 8 av 14
B26: Vinner gruppe F? | C26: {=INDEX(Data!AJ2:AJ15,MATCH(MAX(COUNTIF(Data!AJ2:AJ15,Data!AJ2:AJ15)),COUNTIF(Data!AJ2:AJ15,Data!AJ2:AJ15),0))} -> Nederland | D26: {=MAX(COUNTIF(Data!AJ2:AJ15,Data!AJ2:AJ15))&" av 14"} -> 14 av 14
B27: Vinner gruppe G? | C27: {=INDEX(Data!AK2:AK15,MATCH(MAX(COUNTIF(Data!AK2:AK15,Data!AK2:AK15)),COUNTIF(Data!AK2:AK15,Data!AK2:AK15),0))} -> Belgia | D27: {=MAX(COUNTIF(Data!AK2:AK15,Data!AK2:AK15))&" av 14"} -> 12 av 14
B28: Toer gruppe I? | C28: {=INDEX(Data!AL2:AL15,MATCH(MAX(COUNTIF(Data!AL2:AL15,Data!AL2:AL15)),COUNTIF(Data!AL2:AL15,Data!AL2:AL15),0))} -> Norge | D28: {=MAX(COUNTIF(Data!AL2:AL15,Data!AL2:AL15))&" av 14"} -> 9 av 14
B29: Går 3. plass i gruppe K videre? | C29: {=INDEX(Data!AM2:AM15,MATCH(MAX(COUNTIF(Data!AM2:AM15,Data!AM2:AM15)),COUNTIF(Data!AM2:AM15,Data!AM2:AM15),0))} -> Nei | D29: {=MAX(COUNTIF(Data!AM2:AM15,Data!AM2:AM15))&" av 14"} -> 13 av 14
B31: 🇳🇴 Norge-spørsmålene
B32: Spørsmål | C32: Ja | D32: Nei
B33: Scorer Norge 7+ mål i gruppespillet? | C33: =COUNTIF(Data!AN2:AN15,"Ja") -> 3 | D33: =COUNTIF(Data!AN2:AN15,"Nei") -> 11
B34: Slipper Norge inn 4+ mål i gruppespillet? | C34: =COUNTIF(Data!AO2:AO15,"Ja") -> 10 | D34: =COUNTIF(Data!AO2:AO15,"Nei") -> 4
B35: Møter Norge Brasil i finalespillet? | C35: =COUNTIF(Data!AP2:AP15,"Ja") -> 3 | D35: =COUNTIF(Data!AP2:AP15,"Nei") -> 11
B37: Når lengst i VM – Norge eller England? | C37: =COUNTIF(Data!AQ2:AQ15,"England")&" × England · "&COUNTIF(Data!AQ2:AQ15,"Norge")&" × Norge · "&COUNTIF(Data!AQ2:AQ15,"Like langt")&" × like langt" -> 13 × England · 0 × Norge · 0 × like langt
B38: Norges toppscorer i VM? | C38: =COUNTIF(Data!AR2:AR15,"Haaland")&" × Haaland · "&COUNTIF(Data!AR2:AR15,"Sørloth")&" × Sørloth · "&COUNTIF(Data!AR2:AR15,"En annen")&" × en annen" -> 12 × Haaland · 2 × Sørloth · 0 × en annen
B40: 🎉 Morsomme funn
B41: • Ingen tror på Norge mot England! Alle som svarte mener England når lengst i VM – og Kari turte ikke én gang å velge.
B42: • Haaland-land: 12 av 14 spår Haaland som Norges toppscorer. Kun Knut og Øystein heier på Sørloth.
B43: • Forsvars-pessimisme: 10 tror Norge slipper inn 4+ mål i gruppespillet, men bare 3 tror på 7+ scoringer.
B44: • Tidenes optimist: AI ga Spania hele 6–0 mot Kapp Verde – turneringens villeste enkelttips.
B45: • Målfest vs. bussparking: Ådne tippet flest mål totalt (35) over de 10 kampene, Jardar færrest (17).
B46: • Senegal-skrekk: Bare Vidar tror Norge taper åpningskampen mot Senegal (2–3). Resten ser seier eller uavgjort.
B47: • Full enighet: Alle 14 mener Nederland vinner gruppe F, og alle 14 tror Tyskland slår Ecuador.
...

Sheet Ark1
A8: ='FIFA World cup 2026'!A9 -> Gruppespillet: | B8: Poeng
A9: ='FIFA World cup 2026'!A10 -> (Tipp sluttresultat i kampene. Rett resultat - H/U/B - gir 1 poeng, rett målscore gir 1 poeng)
A10: ='FIFA World cup 2026'!A11 -> Gruppe A: Torsdag 11.06.2026 21:00 Mexico - Sør-Afrika | B10: 2
A11: ='FIFA World cup 2026'!A12 -> Gruppe C: Søndag 14.06.2026 00:00 Brasil - Marokko | B11: 2
A12: ='FIFA World cup 2026'!A13 -> Gruppe H: Mandag 15.06.2026 18:00 Spania - Kapp Verde | B12: 2
A13: ='FIFA World cup 2026'!A14 -> Gruppe J: Tirsdag 17.06.2026 03:00 Argentina - Algerie | B13: 2
A14: ='FIFA World cup 2026'!A15 -> Gruppe L: Onsdag 17.06.2026 22:00 England - Kroatia | B14: 2
A15: ='FIFA World cup 2026'!A16 -> Gruppe F: Lørdag 20.06.2026 19:00 Nederland - Sverige | B15: 2
A16: ='FIFA World cup 2026'!A17 -> Gruppe I: Tirsdag 23.06.2026 02:00 Norge - Senegal | B16: 2
A17: ='FIFA World cup 2026'!A18 -> Gruppe E: Torsdag 25.06.2026 22:00 Ecuador - Tyskland | B17: 2
A18: ='FIFA World cup 2026'!A19 -> Gruppe I: Fredag 26.06.2026 21:00 Norge - Frankrike | B18: 2
A19: ='FIFA World cup 2026'!A20 -> Gruppe K: Lørdag 27.06.2026 02:00 Colombia - Portugal | B19: 2
A21: ='FIFA World cup 2026'!A22 -> (Tipp sluttresultater i gruppene, 2 poeng for hvert rett svar)
A22: ='FIFA World cup 2026'!A23 -> Hvem blir vinner i gruppe A? | B22: 2
A23: ='FIFA World cup 2026'!A24 -> Hvem blir toer i gruppe B? | B23: 2
A24: ='FIFA World cup 2026'!A25 -> Går 3. plass i gruppe C videre? (J/N) | B24: 2
A25: ='FIFA World cup 2026'!A26 -> Hvem blir vinner i gruppe D? | B25: 2
A26: ='FIFA World cup 2026'!A27 -> Hvem blir vinner i gruppe F? | B26: 2
A27: ='FIFA World cup 2026'!A28 -> Hvem blir vinner i gruppe G? | B27: 2
A28: ='FIFA World cup 2026'!A29 -> Hvem blir toer i gruppe I? | B28: 2
A29: ='FIFA World cup 2026'!A30 -> Går 3.plass i gruppe K videre? (J/N) | B29: 2
A31: ='FIFA World cup 2026'!A32 -> Norge:
A32: ='FIFA World cup 2026'!A33 -> (2 poeng for hvert rett svar)
A33: ='FIFA World cup 2026'!A34 -> Kommer Norge til å score 7 mål eller mer i gruppespillet? (J/N) | B33: 2
A34: ='FIFA World cup 2026'!A35 -> Kommer Norge til å slippe inn 4 mål eller mer i gruppespillet? (J/N) | B34: 2
A35: ='FIFA World cup 2026'!A36 -> Kommer Norge til å møte Brasil i finalespillet? (J/N) | B35: 2
A36: ='FIFA World cup 2026'!A37 -> Hvem når lengst i VM av Norge og England? (Kryss av) | B36: 2
A37: ='FIFA World cup 2026'!A38 -> Hvem blir Norges toppscorer? (Kryss av) | B37: 2
A39: ='FIFA World cup 2026'!A40 -> Finalespillet:
A40: ='FIFA World cup 2026'!A41 -> (2 poeng for hvert rett svar)
A41: ='FIFA World cup 2026'!A42 -> Går Sverige videre fra gruppespillet? (J/N) | B41: 2
A42: ='FIFA World cup 2026'!A43 -> Hvor mange europeiske lag går til sekstendedelsfinale? | B42: 2
A43: ='FIFA World cup 2026'!A44 -> Hvilke av vertsnasjonene går videre til åttendedelsfinale? | B43: 2
A44: ='FIFA World cup 2026'!A45 -> Hvilke 8 land går videre til kvartfinaler? Fyll inn
A45: ='FIFA World cup 2026'!A46 -> Lag 1: | B45: 2
A46: ='FIFA World cup 2026'!A47 -> Lag 2: | B46: 2
A47: ='FIFA World cup 2026'!A48 -> Lag 3: | B47: 2
A48: ='FIFA World cup 2026'!A49 -> Lag 4: | B48: 2
A49: ='FIFA World cup 2026'!A50 -> Lag 5: | B49: 2
A50: ='FIFA World cup 2026'!A51 -> Lag 6: | B50: 2
...

Sheet Ahilan
A1: "Av alle uviktige ting i verden er fotball den aller viktigste" (pave Johannes Paul II)
A2: Gruppene:
A3: A: | B3: B: | C3: C: | E3: D: | F3: E: | K3: F: | N3: G: | S3: H: | Y3: I: | AC3: J: | AG3: K: | AK3: L:
A4: Mexico | B4: Canada | C4: Brasil | E4: USA | F4: Tyskland | K4: Nederland | N4: Belgia | S4: Spania | Y4: Frankrike | AC4: Argentina | AG4: Portugal | AK4: England
A5: Sør-Afrika | B5: Qatar | C5: Marokko | E5: Tyrkia | F5: Elfenbenskysten | K5: Japan | N5: Iran | S5: Saudi-Arabia | Y5: Norge | AC5: Østerrike | AG5: Usbekistan | AK5: Kroatia
A6: Sør-Korea | B6: Bosnia-Herceg. | C6: Haiti | E6: Australia | F6: Ecuador | K6: Sverige | N6: Egypt | S6: Uruguay | Y6: Irak | AC6: Jordan | AG6: Colombia | AK6: Panama
A7: Tsjekkia | B7: Sveits | C7: Skottland | E7: Paraguay | F7: Curacao | K7: Tunisia | N7: New Zealand | S7: Kapp Verde | Y7: Senegal | AC7: Algerie | AG7: DR Kongo | AK7: Ghana
A9: Gruppespillet:
A10: (Tipp sluttresultat i kampene. Rett resultat - H/U/B - gir 1 poeng, rett målscore gir 1 poeng)
A11: Gruppe A: Torsdag 11.06.2026 21:00 Mexico - Sør-Afrika | F11: 2 | G11: - | H11: 0
A12: Gruppe C: Søndag 14.06.2026 00:00 Brasil - Marokko | F12: 1 | G12: - | H12: 0
A13: Gruppe H: Mandag 15.06.2026 18:00 Spania - Kapp Verde | F13: 3 | G13: - | H13: 0
A14: Gruppe J: Tirsdag 17.06.2026 03:00 Argentina - Algerie | F14: 2 | G14: - | H14: 1
A15: Gruppe L: Onsdag 17.06.2026 22:00 England - Kroatia | F15: 0 | G15: - | H15: 0
A16: Gruppe F: Lørdag 20.06.2026 19:00 Nederland - Sverige | F16: 2 | G16: - | H16: 1
A17: Gruppe I: Tirsdag 23.06.2026 02:00 Norge - Senegal | F17: 0 | G17: - | H17: 0
A18: Gruppe E: Torsdag 25.06.2026 22:00 Ecuador - Tyskland | F18: 0 | G18: - | H18: 1
A19: Gruppe I: Fredag 26.06.2026 21:00 Norge - Frankrike | F19: 0 | G19: - | H19: 1
A20: Gruppe K: Lørdag 27.06.2026 02:00 Colombia - Portugal | F20: 2 | G20: - | H20: 3
A22: (Tipp sluttresultater i gruppene, 2 poeng for hvert rett svar)
A23: Hvem blir vinner i gruppe A? | C23: Tsjekkia
A24: Hvem blir toer i gruppe B? | C24: Sveits
A25: Går 3. plass i gruppe C videre? (J/N) | C25: N
A26: Hvem blir vinner i gruppe D? | C26: Tyrkia
A27: Hvem blir vinner i gruppe F? | C27: Nederland
A28: Hvem blir vinner i gruppe G? | C28: Belgia
A29: Hvem blir toer i gruppe I? | C29: Senegal
A30: Går 3.plass i gruppe K videre? (J/N) | C30: N
A32: Norge:
A33: (2 poeng for hvert rett svar)
A34: Kommer Norge til å score 7 mål eller mer i gruppespillet? (J/N) | F34: N
A35: Kommer Norge til å slippe inn 4 mål eller mer i gruppespillet? (J/N) | F35: N
A36: Kommer Norge til å møte Brasil i finalespillet? (J/N) | F36: N
A37: Hvem når lengst i VM av Norge og England? (Kryss av) | I37: Norge: | K37: England: | L37: X | M37: Like langt:
A38: Hvem blir Norges toppscorer? (Kryss av) | I38: Haaland: | J38: X | K38: Sørloth: | M38: En annen:
A40: Finalespillet:
A41: (2 poeng for hvert rett svar)
A42: Går Sverige videre fra gruppespillet? (J/N) | F42: N
A43: Hvor mange europeiske lag går til sekstendedelsfinale? | F43: 8
A44: Hvilke av vertsnasjonene går videre til åttendedelsfinale? | F44: Mexico
...

Sheet Haakon
A1: "Av alle uviktige ting i verden er fotball den aller viktigste" (pave Johannes Paul II)
A2: Gruppene:
A3: A: | B3: B: | C3: C: | E3: D: | F3: E: | K3: F: | N3: G: | S3: H: | Y3: I: | AC3: J: | AG3: K: | AK3: L:
A4: Mexico | B4: Canada | C4: Brasil | E4: USA | F4: Tyskland | K4: Nederland | N4: Belgia | S4: Spania | Y4: Frankrike | AC4: Argentina | AG4: Portugal | AK4: England
A5: Sør-Afrika | B5: Qatar | C5: Marokko | E5: Tyrkia | F5: Elfenbenskysten | K5: Japan | N5: Iran | S5: Saudi-Arabia | Y5: Norge | AC5: Østerrike | AG5: Usbekistan | AK5: Kroatia
A6: Sør-Korea | B6: Bosnia-Herceg. | C6: Haiti | E6: Australia | F6: Ecuador | K6: Sverige | N6: Egypt | S6: Uruguay | Y6: Irak | AC6: Jordan | AG6: Colombia | AK6: Panama
A7: Tsjekkia | B7: Sveits | C7: Skottland | E7: Paraguay | F7: Curacao | K7: Tunisia | N7: New Zealand | S7: Kapp Verde | Y7: Senegal | AC7: Algerie | AG7: DR Kongo | AK7: Ghana
A9: Gruppespillet:
A10: (Tipp sluttresultat i kampene. Rett resultat - H/U/B - gir 1 poeng, rett målscore gir 1 poeng)
A11: Gruppe A: Torsdag 11.06.2026 21:00 Mexico - Sør-Afrika | F11: 3 | G11: - | H11: 0
A12: Gruppe C: Søndag 14.06.2026 00:00 Brasil - Marokko | F12: 3 | G12: - | H12: 2
A13: Gruppe H: Mandag 15.06.2026 18:00 Spania - Kapp Verde | F13: 4 | G13: - | H13: 0
A14: Gruppe J: Tirsdag 17.06.2026 03:00 Argentina - Algerie | F14: 3 | G14: - | H14: 1
A15: Gruppe L: Onsdag 17.06.2026 22:00 England - Kroatia | F15: 3 | G15: - | H15: 0
A16: Gruppe F: Lørdag 20.06.2026 19:00 Nederland - Sverige | F16: 2 | G16: - | H16: 0
A17: Gruppe I: Tirsdag 23.06.2026 02:00 Norge - Senegal | F17: 2 | G17: - | H17: 1
A18: Gruppe E: Torsdag 25.06.2026 22:00 Ecuador - Tyskland | F18: 1 | G18: - | H18: 2
A19: Gruppe I: Fredag 26.06.2026 21:00 Norge - Frankrike | F19: 2 | G19: - | H19: 2
A20: Gruppe K: Lørdag 27.06.2026 02:00 Colombia - Portugal | F20: 1 | G20: - | H20: 2
A22: (Tipp sluttresultater i gruppene, 2 poeng for hvert rett svar)
A23: Hvem blir vinner i gruppe A? | C23: Mexico
A24: Hvem blir toer i gruppe B? | C24: Sveits
A25: Går 3. plass i gruppe C videre? (J/N) | C25: J
A26: Hvem blir vinner i gruppe D? | C26: USA
A27: Hvem blir vinner i gruppe F? | C27: Nederland
A28: Hvem blir vinner i gruppe G? | C28: Belgia
A29: Hvem blir toer i gruppe I? | C29: Norge
A30: Går 3.plass i gruppe K videre? (J/N) | C30: N
A32: Norge:
A33: (2 poeng for hvert rett svar)
A34: Kommer Norge til å score 7 mål eller mer i gruppespillet? (J/N) | F34: J
A35: Kommer Norge til å slippe inn 4 mål eller mer i gruppespillet? (J/N) | F35: J
A36: Kommer Norge til å møte Brasil i finalespillet? (J/N) | F36: J
A37: Hvem når lengst i VM av Norge og England? (Kryss av) | I37: Norge: | K37: England: | L37: X | M37: Like langt:
A38: Hvem blir Norges toppscorer? (Kryss av) | I38: Haaland: | J38: X | K38: Sørloth: | M38: En annen:
A40: Finalespillet:
A41: (2 poeng for hvert rett svar)
A42: Går Sverige videre fra gruppespillet? (J/N) | F42: J
A43: Hvor mange europeiske lag går til sekstendedelsfinale? | F43: 9
A44: Hvilke av vertsnasjonene går videre til åttendedelsfinale? | F44: Ingen
...

Sheet AI
A1: "Av alle uviktige ting i verden er fotball den aller viktigste" (pave Johannes Paul II)
A2: Gruppene:
A3: A: | B3: B: | C3: C: | E3: D: | F3: E: | K3: F: | N3: G: | S3: H: | Y3: I: | AC3: J: | AG3: K: | AK3: L:
A4: Mexico | B4: Canada | C4: Brasil | E4: USA | F4: Tyskland | K4: Nederland | N4: Belgia | S4: Spania | Y4: Frankrike | AC4: Argentina | AG4: Portugal | AK4: England
A5: Sør-Afrika | B5: Qatar | C5: Marokko | E5: Tyrkia | F5: Elfenbenskysten | K5: Japan | N5: Iran | S5: Saudi-Arabia | Y5: Norge | AC5: Østerrike | AG5: Usbekistan | AK5: Kroatia
A6: Sør-Korea | B6: Bosnia-Herceg. | C6: Haiti | E6: Australia | F6: Ecuador | K6: Sverige | N6: Egypt | S6: Uruguay | Y6: Irak | AC6: Jordan | AG6: Colombia | AK6: Panama
A7: Tsjekkia | B7: Sveits | C7: Skottland | E7: Paraguay | F7: Curacao | K7: Tunisia | N7: New Zealand | S7: Kapp Verde | Y7: Senegal | AC7: Algerie | AG7: DR Kongo | AK7: Ghana
A9: Gruppespillet:
A10: (Tipp sluttresultat i kampene. Rett resultat - H/U/B - gir 1 poeng, rett målscore gir 1 poeng)
A11: Gruppe A: Torsdag 11.06.2026 21:00 Mexico - Sør-Afrika | F11: 2 | G11: - | H11: 1
A12: Gruppe C: Søndag 14.06.2026 00:00 Brasil - Marokko | F12: 3 | G12: - | H12: 1
A13: Gruppe H: Mandag 15.06.2026 18:00 Spania - Kapp Verde | F13: 6 | G13: - | H13: 0
A14: Gruppe J: Tirsdag 17.06.2026 03:00 Argentina - Algerie | F14: 3 | G14: - | H14: 0
A15: Gruppe L: Onsdag 17.06.2026 22:00 England - Kroatia | F15: 2 | G15: - | H15: 2
A16: Gruppe F: Lørdag 20.06.2026 19:00 Nederland - Sverige | F16: 2 | G16: - | H16: 1
A17: Gruppe I: Tirsdag 23.06.2026 02:00 Norge - Senegal | F17: 1 | G17: - | H17: 0
A18: Gruppe E: Torsdag 25.06.2026 22:00 Ecuador - Tyskland | F18: 1 | G18: - | H18: 2
A19: Gruppe I: Fredag 26.06.2026 21:00 Norge - Frankrike | F19: 2 | G19: - | H19: 2
A20: Gruppe K: Lørdag 27.06.2026 02:00 Colombia - Portugal | F20: 1 | G20: - | H20: 2
A22: (Tipp sluttresultater i gruppene, 2 poeng for hvert rett svar)
A23: Hvem blir vinner i gruppe A? | C23: Mexico
A24: Hvem blir toer i gruppe B? | C24: Sveits
A25: Går 3. plass i gruppe C videre? (J/N) | C25: J
A26: Hvem blir vinner i gruppe D? | C26: USA
A27: Hvem blir vinner i gruppe F? | C27: Nederland
A28: Hvem blir vinner i gruppe G? | C28: Belgia
A29: Hvem blir toer i gruppe I? | C29: Norge
A30: Går 3.plass i gruppe K videre? (J/N) | C30: N
A32: Norge:
A33: (2 poeng for hvert rett svar)
A34: Kommer Norge til å score 7 mål eller mer i gruppespillet? (J/N) | F34: J
A35: Kommer Norge til å slippe inn 4 mål eller mer i gruppespillet? (J/N) | F35: J
A36: Kommer Norge til å møte Brasil i finalespillet? (J/N) | F36: N
A37: Hvem når lengst i VM av Norge og England? (Kryss av) | I37: Norge: | K37: England: | L37: X | M37: Like langt:
A38: Hvem blir Norges toppscorer? (Kryss av) | I38: Haaland: | J38: X | K38: Sørloth: | M38: En annen:
A40: Finalespillet:
A41: (2 poeng for hvert rett svar)
A42: Går Sverige videre fra gruppespillet? (J/N) | F42: J
A43: Hvor mange europeiske lag går til sekstendedelsfinale? | F43: 15
A44: Hvilke av vertsnasjonene går videre til åttendedelsfinale? | F44: USA
...

Sheet Jardar
A1: "Av alle uviktige ting i verden er fotball den aller viktigste" (pave Johannes Paul II)
A2: Gruppene:
A3: A: | B3: B: | C3: C: | E3: D: | F3: E: | K3: F: | N3: G: | S3: H: | Y3: I: | AC3: J: | AG3: K: | AK3: L:
A4: Mexico | B4: Canada | C4: Brasil | E4: USA | F4: Tyskland | K4: Nederland | N4: Belgia | S4: Spania | Y4: Frankrike | AC4: Argentina | AG4: Portugal | AK4: England
A5: Sør-Afrika | B5: Qatar | C5: Marokko | E5: Tyrkia | F5: Elfenbenskysten | K5: Japan | N5: Iran | S5: Saudi-Arabia | Y5: Norge | AC5: Østerrike | AG5: Usbekistan | AK5: Kroatia
A6: Sør-Korea | B6: Bosnia-Herceg. | C6: Haiti | E6: Australia | F6: Ecuador | K6: Sverige | N6: Egypt | S6: Uruguay | Y6: Irak | AC6: Jordan | AG6: Colombia | AK6: Panama
A7: Tsjekkia | B7: Sveits | C7: Skottland | E7: Paraguay | F7: Curacao | K7: Tunisia | N7: New Zealand | S7: Kapp Verde | Y7: Senegal | AC7: Algerie | AG7: DR Kongo | AK7: Ghana
A9: Gruppespillet:
A10: (Tipp sluttresultat i kampene. Rett resultat - H/U/B - gir 1 poeng, rett målscore gir 1 poeng)
A11: Gruppe A: Torsdag 11.06.2026 21:00 Mexico - Sør-Afrika | F11: 2 | G11: - | H11: 0
A12: Gruppe C: Søndag 14.06.2026 00:00 Brasil - Marokko | F12: 0 | G12: - | H12: 0
A13: Gruppe H: Mandag 15.06.2026 18:00 Spania - Kapp Verde | F13: 3 | G13: - | H13: 0
A14: Gruppe J: Tirsdag 17.06.2026 03:00 Argentina - Algerie | F14: 1 | G14: - | H14: 0
A15: Gruppe L: Onsdag 17.06.2026 22:00 England - Kroatia | F15: 1 | G15: - | H15: 1
A16: Gruppe F: Lørdag 20.06.2026 19:00 Nederland - Sverige | F16: 2 | G16: - | H16: 0
A17: Gruppe I: Tirsdag 23.06.2026 02:00 Norge - Senegal | F17: 1 | G17: - | H17: 0
A18: Gruppe E: Torsdag 25.06.2026 22:00 Ecuador - Tyskland | F18: 0 | G18: - | H18: 2
A19: Gruppe I: Fredag 26.06.2026 21:00 Norge - Frankrike | F19: 2 | G19: - | H19: 1
A20: Gruppe K: Lørdag 27.06.2026 02:00 Colombia - Portugal | F20: 0 | G20: - | H20: 1
A22: (Tipp sluttresultater i gruppene, 2 poeng for hvert rett svar)
A23: Hvem blir vinner i gruppe A? | C23: Mexico
A24: Hvem blir toer i gruppe B? | C24: Bosnia
A25: Går 3. plass i gruppe C videre? (J/N) | C25: J
A26: Hvem blir vinner i gruppe D? | C26: Paraguay
A27: Hvem blir vinner i gruppe F? | C27: Nederland
A28: Hvem blir vinner i gruppe G? | C28: Belgia
A29: Hvem blir toer i gruppe I? | C29: Senegal
A30: Går 3.plass i gruppe K videre? (J/N) | C30: J
A32: Norge:
A33: (2 poeng for hvert rett svar)
A34: Kommer Norge til å score 7 mål eller mer i gruppespillet? (J/N) | F34: N
A35: Kommer Norge til å slippe inn 4 mål eller mer i gruppespillet? (J/N) | F35: N
A36: Kommer Norge til å møte Brasil i finalespillet? (J/N) | F36: N
A37: Hvem når lengst i VM av Norge og England? (Kryss av) | I37: Norge: | K37: England: | L37: X | M37: Like langt:
A38: Hvem blir Norges toppscorer? (Kryss av) | I38: Haaland: | J38: X | K38: Sørloth: | M38: En annen:
A40: Finalespillet:
A41: (2 poeng for hvert rett svar)
A42: Går Sverige videre fra gruppespillet? (J/N) | F42: N
A43: Hvor mange europeiske lag går til sekstendedelsfinale? | F43: 16
A44: Hvilke av vertsnasjonene går videre til åttendedelsfinale? | F44: Mexico
...

Sheet Kari
A1: "Av alle uviktige ting i verden er fotball den aller viktigste" (pave Johannes Paul II)
A2: Gruppene:
A3: A: | B3: B: | C3: C: | E3: D: | F3: E: | K3: F: | N3: G: | S3: H: | Y3: I: | AC3: J: | AG3: K: | AK3: L:
A4: Mexico | B4: Canada | C4: Brasil | E4: USA | F4: Tyskland | K4: Nederland | N4: Belgia | S4: Spania | Y4: Frankrike | AC4: Argentina | AG4: Portugal | AK4: England
A5: Sør-Afrika | B5: Qatar | C5: Marokko | E5: Tyrkia | F5: Elfenbenskysten | K5: Japan | N5: Iran | S5: Saudi-Arabia | Y5: Norge | AC5: Østerrike | AG5: Usbekistan | AK5: Kroatia
A6: Sør-Korea | B6: Bosnia-Herceg. | C6: Haiti | E6: Australia | F6: Ecuador | K6: Sverige | N6: Egypt | S6: Uruguay | Y6: Irak | AC6: Jordan | AG6: Colombia | AK6: Panama
A7: Tsjekkia | B7: Sveits | C7: Skottland | E7: Paraguay | F7: Curacao | K7: Tunisia | N7: New Zealand | S7: Kapp Verde | Y7: Senegal | AC7: Algerie | AG7: DR Kongo | AK7: Ghana
A9: Gruppespillet:
A10: (Tipp sluttresultat i kampene. Rett resultat - H/U/B - gir 1 poeng, rett målscore gir 1 poeng)
A11: Gruppe A: Torsdag 11.06.2026 21:00 Mexico - Sør-Afrika | F11: 2 | G11: - | H11: 1
A12: Gruppe C: Søndag 14.06.2026 00:00 Brasil - Marokko | F12: 1 | G12: - | H12: 1
A13: Gruppe H: Mandag 15.06.2026 18:00 Spania - Kapp Verde | F13: 3 | G13: - | H13: 0
A14: Gruppe J: Tirsdag 17.06.2026 03:00 Argentina - Algerie | F14: 2 | G14: - | H14: 1
A15: Gruppe L: Onsdag 17.06.2026 22:00 England - Kroatia | F15: 1 | G15: - | H15: 1
A16: Gruppe F: Lørdag 20.06.2026 19:00 Nederland - Sverige | F16: 2 | G16: - | H16: 0
A17: Gruppe I: Tirsdag 23.06.2026 02:00 Norge - Senegal | F17: 1 | G17: - | H17: 1
A18: Gruppe E: Torsdag 25.06.2026 22:00 Ecuador - Tyskland | F18: 0 | G18: - | H18: 1
A19: Gruppe I: Fredag 26.06.2026 21:00 Norge - Frankrike | F19: 1 | G19: - | H19: 3
A20: Gruppe K: Lørdag 27.06.2026 02:00 Colombia - Portugal | F20: 0 | G20: - | H20: 2
A22: (Tipp sluttresultater i gruppene, 2 poeng for hvert rett svar)
A23: Hvem blir vinner i gruppe A? | C23: Mexico
A24: Hvem blir toer i gruppe B? | C24: Sveits
A25: Går 3. plass i gruppe C videre? (J/N) | C25: J
A26: Hvem blir vinner i gruppe D? | C26: Tyrkia
A27: Hvem blir vinner i gruppe F? | C27: Nederland
A28: Hvem blir vinner i gruppe G? | C28: Belgia
A29: Hvem blir toer i gruppe I? | C29: Norge
A30: Går 3.plass i gruppe K videre? (J/N) | C30: N
A32: Norge:
A33: (2 poeng for hvert rett svar)
A34: Kommer Norge til å score 7 mål eller mer i gruppespillet? (J/N) | F34: N
A35: Kommer Norge til å slippe inn 4 mål eller mer i gruppespillet? (J/N) | F35: J
A36: Kommer Norge til å møte Brasil i finalespillet? (J/N) | F36: N
A37: Hvem når lengst i VM av Norge og England? (Kryss av) | I37: Norge: | K37: England: | M37: Like langt: | R37: X
A38: Hvem blir Norges toppscorer? (Kryss av) | I38: Haaland: | J38: X | K38: Sørloth: | M38: En annen:
A40: Finalespillet:
A41: (2 poeng for hvert rett svar)
A42: Går Sverige videre fra gruppespillet? (J/N) | F42: N
A43: Hvor mange europeiske lag går til sekstendedelsfinale? | F43: 13
A44: Hvilke av vertsnasjonene går videre til åttendedelsfinale? | F44: Mexico
...

Sheet Knut
A1: "Av alle uviktige ting i verden er fotball den aller viktigste" (pave Johannes Paul II)
A2: Gruppene:
A3: A: | B3: B: | C3: C: | E3: D: | F3: E: | K3: F: | N3: G: | S3: H: | Y3: I: | AC3: J: | AG3: K: | AK3: L:
A4: Mexico | B4: Canada | C4: Brasil | E4: USA | F4: Tyskland | K4: Nederland | N4: Belgia | S4: Spania | Y4: Frankrike | AC4: Argentina | AG4: Portugal | AK4: England
A5: Sør-Afrika | B5: Qatar | C5: Marokko | E5: Tyrkia | F5: Elfenbenskysten | K5: Japan | N5: Iran | S5: Saudi-Arabia | Y5: Norge | AC5: Østerrike | AG5: Usbekistan | AK5: Kroatia
A6: Sør-Korea | B6: Bosnia-Herceg. | C6: Haiti | E6: Australia | F6: Ecuador | K6: Sverige | N6: Egypt | S6: Uruguay | Y6: Irak | AC6: Jordan | AG6: Colombia | AK6: Panama
A7: Tsjekkia | B7: Sveits | C7: Skottland | E7: Paraguay | F7: Curacao | K7: Tunisia | N7: New Zealand | S7: Kapp Verde | Y7: Senegal | AC7: Algerie | AG7: DR Kongo | AK7: Ghana
A9: Gruppespillet:
A10: (Tipp sluttresultat i kampene. Rett resultat - H/U/B - gir 1 poeng, rett målscore gir 1 poeng)
A11: Gruppe A: Torsdag 11.06.2026 21:00 Mexico - Sør-Afrika | F11: 1 | G11: - | H11: 0
A12: Gruppe C: Søndag 14.06.2026 00:00 Brasil - Marokko | F12: 2 | G12: - | H12: 1
A13: Gruppe H: Mandag 15.06.2026 18:00 Spania - Kapp Verde | F13: 1 | G13: - | H13: 1
A14: Gruppe J: Tirsdag 17.06.2026 03:00 Argentina - Algerie | F14: 0 | G14: - | H14: 1
A15: Gruppe L: Onsdag 17.06.2026 22:00 England - Kroatia | F15: 3 | G15: - | H15: 0
A16: Gruppe F: Lørdag 20.06.2026 19:00 Nederland - Sverige | F16: 2 | G16: - | H16: 1
A17: Gruppe I: Tirsdag 23.06.2026 02:00 Norge - Senegal | F17: 2 | G17: - | H17: 2
A18: Gruppe E: Torsdag 25.06.2026 22:00 Ecuador - Tyskland | F18: 0 | G18: - | H18: 1
A19: Gruppe I: Fredag 26.06.2026 21:00 Norge - Frankrike | F19: 1 | G19: - | H19: 3
A20: Gruppe K: Lørdag 27.06.2026 02:00 Colombia - Portugal | F20: 0 | G20: - | H20: 0
A22: (Tipp sluttresultater i gruppene, 2 poeng for hvert rett svar)
A23: Hvem blir vinner i gruppe A? | C23: Sør-Korea
A24: Hvem blir toer i gruppe B? | C24: Canada
A25: Går 3. plass i gruppe C videre? (J/N) | C25: J
A26: Hvem blir vinner i gruppe D? | C26: Tyrkia
A27: Hvem blir vinner i gruppe F? | C27: Nederland
A28: Hvem blir vinner i gruppe G? | C28: Belgia
A29: Hvem blir toer i gruppe I? | C29: Norge
A30: Går 3.plass i gruppe K videre? (J/N) | C30: N
A32: Norge:
A33: (2 poeng for hvert rett svar)
A34: Kommer Norge til å score 7 mål eller mer i gruppespillet? (J/N) | F34: N
A35: Kommer Norge til å slippe inn 4 mål eller mer i gruppespillet? (J/N) | F35: J
A36: Kommer Norge til å møte Brasil i finalespillet? (J/N) | F36: J
A37: Hvem når lengst i VM av Norge og England? (Kryss av) | I37: Norge: | K37: England: | L37: x | M37: Like langt:
A38: Hvem blir Norges toppscorer? (Kryss av) | I38: Haaland: | K38: Sørloth: | L38: x | M38: En annen:
A40: Finalespillet:
A41: (2 poeng for hvert rett svar)
A42: Går Sverige videre fra gruppespillet? (J/N) | F42: N
A43: Hvor mange europeiske lag går til sekstendedelsfinale? | F43: 14
A44: Hvilke av vertsnasjonene går videre til åttendedelsfinale? | F44: Mexico, USA
...

Sheet Leif Anders
A1: "Av alle uviktige ting i verden er fotball den aller viktigste" (pave Johannes Paul II)
A2: Gruppene:
A3: A: | B3: B: | C3: C: | E3: D: | F3: E: | K3: F: | N3: G: | S3: H: | Y3: I: | AC3: J: | AG3: K: | AK3: L:
A4: Mexico | B4: Canada | C4: Brasil | E4: USA | F4: Tyskland | K4: Nederland | N4: Belgia | S4: Spania | Y4: Frankrike | AC4: Argentina | AG4: Portugal | AK4: England
A5: Sør-Afrika | B5: Qatar | C5: Marokko | E5: Tyrkia | F5: Elfenbenskysten | K5: Japan | N5: Iran | S5: Saudi-Arabia | Y5: Norge | AC5: Østerrike | AG5: Usbekistan | AK5: Kroatia
A6: Sør-Korea | B6: Bosnia-Herceg. | C6: Haiti | E6: Australia | F6: Ecuador | K6: Sverige | N6: Egypt | S6: Uruguay | Y6: Irak | AC6: Jordan | AG6: Colombia | AK6: Panama
A7: Tsjekkia | B7: Sveits | C7: Skottland | E7: Paraguay | F7: Curacao | K7: Tunisia | N7: New Zealand | S7: Kapp Verde | Y7: Senegal | AC7: Algerie | AG7: DR Kongo | AK7: Ghana
A9: Gruppespillet:
A10: (Tipp sluttresultat i kampene. Rett resultat - H/U/B - gir 1 poeng, rett målscore gir 1 poeng)
A11: Gruppe A: Torsdag 11.06.2026 21:00 Mexico - Sør-Afrika | F11: 2 | G11: - | H11: 0
A12: Gruppe C: Søndag 14.06.2026 00:00 Brasil - Marokko | F12: 2 | G12: - | H12: 1
A13: Gruppe H: Mandag 15.06.2026 18:00 Spania - Kapp Verde | F13: 4 | G13: - | H13: 0
A14: Gruppe J: Tirsdag 17.06.2026 03:00 Argentina - Algerie | F14: 3 | G14: - | H14: 1
A15: Gruppe L: Onsdag 17.06.2026 22:00 England - Kroatia | F15: 1 | G15: - | H15: 0
A16: Gruppe F: Lørdag 20.06.2026 19:00 Nederland - Sverige | F16: 2 | G16: - | H16: 1
A17: Gruppe I: Tirsdag 23.06.2026 02:00 Norge - Senegal | F17: 1 | G17: - | H17: 1
A18: Gruppe E: Torsdag 25.06.2026 22:00 Ecuador - Tyskland | F18: 0 | G18: - | H18: 1
A19: Gruppe I: Fredag 26.06.2026 21:00 Norge - Frankrike | F19: 1 | G19: - | H19: 3
A20: Gruppe K: Lørdag 27.06.2026 02:00 Colombia - Portugal | F20: 0 | G20: - | H20: 1
A22: (Tipp sluttresultater i gruppene, 2 poeng for hvert rett svar)
A23: Hvem blir vinner i gruppe A? | C23: Mexico
A24: Hvem blir toer i gruppe B? | C24: Canada
A25: Går 3. plass i gruppe C videre? (J/N) | C25: Ja
A26: Hvem blir vinner i gruppe D? | C26: USA
A27: Hvem blir vinner i gruppe F? | C27: Nederland
A28: Hvem blir vinner i gruppe G? | C28: Belgia
A29: Hvem blir toer i gruppe I? | C29: Norge
A30: Går 3.plass i gruppe K videre? (J/N) | C30: Nei
A32: Norge:
A33: (2 poeng for hvert rett svar)
A34: Kommer Norge til å score 7 mål eller mer i gruppespillet? (J/N) | F34: N
A35: Kommer Norge til å slippe inn 4 mål eller mer i gruppespillet? (J/N) | F35: N
A36: Kommer Norge til å møte Brasil i finalespillet? (J/N) | F36: N
A37: Hvem når lengst i VM av Norge og England? (Kryss av) | I37: Norge: | K37: England: | L37: X | M37: Like langt:
A38: Hvem blir Norges toppscorer? (Kryss av) | I38: Haaland: | J38: X | K38: Sørloth: | M38: En annen:
A40: Finalespillet:
A41: (2 poeng for hvert rett svar)
A42: Går Sverige videre fra gruppespillet? (J/N) | F42: J
A43: Hvor mange europeiske lag går til sekstendedelsfinale? | F43: 13
A44: Hvilke av vertsnasjonene går videre til åttendedelsfinale? | F44: USA, Mexico
...

Sheet Magnus
A1: "Av alle uviktige ting i verden er fotball den aller viktigste" (pave Johannes Paul II)
A2: Gruppene:
A3: A: | B3: B: | C3: C: | E3: D: | F3: E: | K3: F: | N3: G: | S3: H: | Y3: I: | AC3: J: | AG3: K: | AK3: L:
A4: Mexico | B4: Canada | C4: Brasil | E4: USA | F4: Tyskland | K4: Nederland | N4: Belgia | S4: Spania | Y4: Frankrike | AC4: Argentina | AG4: Portugal | AK4: England
A5: Sør-Afrika | B5: Qatar | C5: Marokko | E5: Tyrkia | F5: Elfenbenskysten | K5: Japan | N5: Iran | S5: Saudi-Arabia | Y5: Norge | AC5: Østerrike | AG5: Usbekistan | AK5: Kroatia
A6: Sør-Korea | B6: Bosnia-Herceg. | C6: Haiti | E6: Australia | F6: Ecuador | K6: Sverige | N6: Egypt | S6: Uruguay | Y6: Irak | AC6: Jordan | AG6: Colombia | AK6: Panama
A7: Tsjekkia | B7: Sveits | C7: Skottland | E7: Paraguay | F7: Curacao | K7: Tunisia | N7: New Zealand | S7: Kapp Verde | Y7: Senegal | AC7: Algerie | AG7: DR Kongo | AK7: Ghana
A9: Gruppespillet:
A10: (Tipp sluttresultat i kampene. Rett resultat - H/U/B - gir 1 poeng, rett målscore gir 1 poeng)
A11: Gruppe A: Torsdag 11.06.2026 21:00 Mexico - Sør-Afrika | F11: 2 | G11: - | H11: 0
A12: Gruppe C: Søndag 14.06.2026 00:00 Brasil - Marokko | F12: 2 | G12: - | H12: 1
A13: Gruppe H: Mandag 15.06.2026 18:00 Spania - Kapp Verde | F13: 3 | G13: - | H13: 0
A14: Gruppe J: Tirsdag 17.06.2026 03:00 Argentina - Algerie | F14: 2 | G14: - | H14: 0
A15: Gruppe L: Onsdag 17.06.2026 22:00 England - Kroatia | F15: 2 | G15: - | H15: 1
A16: Gruppe F: Lørdag 20.06.2026 19:00 Nederland - Sverige | F16: 2 | G16: - | H16: 0
A17: Gruppe I: Tirsdag 23.06.2026 02:00 Norge - Senegal | F17: 2 | G17: - | H17: 1
A18: Gruppe E: Torsdag 25.06.2026 22:00 Ecuador - Tyskland | F18: 0 | G18: - | H18: 1
A19: Gruppe I: Fredag 26.06.2026 21:00 Norge - Frankrike | F19: 1 | G19: - | H19: 2
A20: Gruppe K: Lørdag 27.06.2026 02:00 Colombia - Portugal | F20: 1 | G20: - | H20: 2
A22: (Tipp sluttresultater i gruppene, 2 poeng for hvert rett svar)
A23: Hvem blir vinner i gruppe A? | C23: Mexico
A24: Hvem blir toer i gruppe B? | C24: Canada
A25: Går 3. plass i gruppe C videre? (J/N) | C25: Ja
A26: Hvem blir vinner i gruppe D? | C26: USA
A27: Hvem blir vinner i gruppe F? | C27: Nederland
A28: Hvem blir vinner i gruppe G? | C28: Belgia
A29: Hvem blir toer i gruppe I? | C29: Norge
A30: Går 3.plass i gruppe K videre? (J/N) | C30: Nei
A32: Norge:
A33: (2 poeng for hvert rett svar)
A34: Kommer Norge til å score 7 mål eller mer i gruppespillet? (J/N) | F34: Ja
A35: Kommer Norge til å slippe inn 4 mål eller mer i gruppespillet? (J/N) | F35: Ja
A36: Kommer Norge til å møte Brasil i finalespillet? (J/N) | F36: Nei
A37: Hvem når lengst i VM av Norge og England? (Kryss av) | I37: Norge: | K37: England: | L37: X | M37: Like langt:
A38: Hvem blir Norges toppscorer? (Kryss av) | I38: Haaland: | J38: X | K38: Sørloth: | M38: En annen:
A40: Finalespillet:
A41: (2 poeng for hvert rett svar)
A42: Går Sverige videre fra gruppespillet? (J/N) | F42: Ja
A43: Hvor mange europeiske lag går til sekstendedelsfinale? | F43: 13
A44: Hvilke av vertsnasjonene går videre til åttendedelsfinale? | F44: Mexico og USA
...

Sheet Malin
A1: "Av alle uviktige ting i verden er fotball den aller viktigste" (pave Johannes Paul II)
A2: Gruppene:
A3: A: | B3: B: | C3: C: | E3: D: | F3: E: | K3: F: | N3: G: | S3: H: | Y3: I: | AC3: J: | AG3: K: | AK3: L:
A4: Mexico | B4: Canada | C4: Brasil | E4: USA | F4: Tyskland | K4: Nederland | N4: Belgia | S4: Spania | Y4: Frankrike | AC4: Argentina | AG4: Portugal | AK4: England
A5: Sør-Afrika | B5: Qatar | C5: Marokko | E5: Tyrkia | F5: Elfenbenskysten | K5: Japan | N5: Iran | S5: Saudi-Arabia | Y5: Norge | AC5: Østerrike | AG5: Usbekistan | AK5: Kroatia
A6: Sør-Korea | B6: Bosnia-Herceg. | C6: Haiti | E6: Australia | F6: Ecuador | K6: Sverige | N6: Egypt | S6: Uruguay | Y6: Irak | AC6: Jordan | AG6: Colombia | AK6: Panama
A7: Tsjekkia | B7: Sveits | C7: Skottland | E7: Paraguay | F7: Curacao | K7: Tunisia | N7: New Zealand | S7: Kapp Verde | Y7: Senegal | AC7: Algerie | AG7: DR Kongo | AK7: Ghana
A9: Gruppespillet:
A10: (Tipp sluttresultat i kampene. Rett resultat - H/U/B - gir 1 poeng, rett målscore gir 1 poeng)
A11: Gruppe A: Torsdag 11.06.2026 21:00 Mexico - Sør-Afrika | F11: 2 | G11: - | H11: 0
A12: Gruppe C: Søndag 14.06.2026 00:00 Brasil - Marokko | F12: 1 | G12: - | H12: 0
A13: Gruppe H: Mandag 15.06.2026 18:00 Spania - Kapp Verde | F13: 3 | G13: - | H13: 0
A14: Gruppe J: Tirsdag 17.06.2026 03:00 Argentina - Algerie | F14: 2 | G14: - | H14: 0
A15: Gruppe L: Onsdag 17.06.2026 22:00 England - Kroatia | F15: 2 | G15: - | H15: 1
A16: Gruppe F: Lørdag 20.06.2026 19:00 Nederland - Sverige | F16: 2 | G16: - | H16: 1
A17: Gruppe I: Tirsdag 23.06.2026 02:00 Norge - Senegal | F17: 2 | G17: - | H17: 0
A18: Gruppe E: Torsdag 25.06.2026 22:00 Ecuador - Tyskland | F18: 0 | G18: - | H18: 2
A19: Gruppe I: Fredag 26.06.2026 21:00 Norge - Frankrike | F19: 1 | G19: - | H19: 2
A20: Gruppe K: Lørdag 27.06.2026 02:00 Colombia - Portugal | F20: 1 | G20: - | H20: 2
A22: (Tipp sluttresultater i gruppene, 2 poeng for hvert rett svar)
A23: Hvem blir vinner i gruppe A? | C23: Mexico
A24: Hvem blir toer i gruppe B? | C24: Canada
A25: Går 3. plass i gruppe C videre? (J/N) | C25: J
A26: Hvem blir vinner i gruppe D? | C26: USA
A27: Hvem blir vinner i gruppe F? | C27: Nederland
A28: Hvem blir vinner i gruppe G? | C28: Belgia
A29: Hvem blir toer i gruppe I? | C29: Norge
A30: Går 3.plass i gruppe K videre? (J/N) | C30: N
A32: Norge:
A33: (2 poeng for hvert rett svar)
A34: Kommer Norge til å score 7 mål eller mer i gruppespillet? (J/N) | F34: N
A35: Kommer Norge til å slippe inn 4 mål eller mer i gruppespillet? (J/N) | F35: J
A36: Kommer Norge til å møte Brasil i finalespillet? (J/N) | F36: N
A37: Hvem når lengst i VM av Norge og England? (Kryss av) | I37: Norge: | K37: England: | L37: X | M37: Like langt:
A38: Hvem blir Norges toppscorer? (Kryss av) | I38: Haaland: | J38: X | K38: Sørloth: | M38: En annen:
A40: Finalespillet:
A41: (2 poeng for hvert rett svar)
A42: Går Sverige videre fra gruppespillet? (J/N) | F42: J
A43: Hvor mange europeiske lag går til sekstendedelsfinale? | F43: 12
A44: Hvilke av vertsnasjonene går videre til åttendedelsfinale? | F44: Mexico og USA
...

Sheet Marit
A1: "Av alle uviktige ting i verden er fotball den aller viktigste" (pave Johannes Paul II)
A2: Gruppene:
A3: A: | B3: B: | C3: C: | E3: D: | F3: E: | K3: F: | N3: G: | S3: H: | Y3: I: | AC3: J: | AG3: K: | AK3: L:
A4: Mexico | B4: Canada | C4: Brasil | E4: USA | F4: Tyskland | K4: Nederland | N4: Belgia | S4: Spania | Y4: Frankrike | AC4: Argentina | AG4: Portugal | AK4: England
A5: Sør-Afrika | B5: Qatar | C5: Marokko | E5: Tyrkia | F5: Elfenbenskysten | K5: Japan | N5: Iran | S5: Saudi-Arabia | Y5: Norge | AC5: Østerrike | AG5: Usbekistan | AK5: Kroatia
A6: Sør-Korea | B6: Bosnia-Herceg. | C6: Haiti | E6: Australia | F6: Ecuador | K6: Sverige | N6: Egypt | S6: Uruguay | Y6: Irak | AC6: Jordan | AG6: Colombia | AK6: Panama
A7: Tsjekkia | B7: Sveits | C7: Skottland | E7: Paraguay | F7: Curacao | K7: Tunisia | N7: New Zealand | S7: Kapp Verde | Y7: Senegal | AC7: Algerie | AG7: DR Kongo | AK7: Ghana
A9: Gruppespillet:
A10: (Tipp sluttresultat i kampene. Rett resultat - H/U/B - gir 1 poeng, rett målscore gir 1 poeng)
A11: Gruppe A: Torsdag 11.06.2026 21:00 Mexico - Sør-Afrika | F11: 2 | G11: - | H11: 0
A12: Gruppe C: Søndag 14.06.2026 00:00 Brasil - Marokko | F12: 2 | G12: - | H12: 1
A13: Gruppe H: Mandag 15.06.2026 18:00 Spania - Kapp Verde | F13: 3 | G13: - | H13: 0
A14: Gruppe J: Tirsdag 17.06.2026 03:00 Argentina - Algerie | F14: 3 | G14: - | H14: 0
A15: Gruppe L: Onsdag 17.06.2026 22:00 England - Kroatia | F15: 1 | G15: - | H15: 1
A16: Gruppe F: Lørdag 20.06.2026 19:00 Nederland - Sverige | F16: 1 | G16: - | H16: 0
A17: Gruppe I: Tirsdag 23.06.2026 02:00 Norge - Senegal | F17: 1 | H17: 1
A18: Gruppe E: Torsdag 25.06.2026 22:00 Ecuador - Tyskland | F18: 1 | G18: - | H18: 3
A19: Gruppe I: Fredag 26.06.2026 21:00 Norge - Frankrike | F19: 1 | G19: - | H19: 2
A20: Gruppe K: Lørdag 27.06.2026 02:00 Colombia - Portugal | F20: 1 | H20: 2
A22: (Tipp sluttresultater i gruppene, 2 poeng for hvert rett svar)
A23: Hvem blir vinner i gruppe A? | C23: Mexico
A24: Hvem blir toer i gruppe B? | C24: Sveits
A25: Går 3. plass i gruppe C videre? (J/N) | C25: ja
A26: Hvem blir vinner i gruppe D? | C26: USA
A27: Hvem blir vinner i gruppe F? | C27: Nederland
A28: Hvem blir vinner i gruppe G? | C28: Belgia
A29: Hvem blir toer i gruppe I? | C29: Senegal
A30: Går 3.plass i gruppe K videre? (J/N) | C30: Nei
A32: Norge:
A33: (2 poeng for hvert rett svar)
A34: Kommer Norge til å score 7 mål eller mer i gruppespillet? (J/N) | F34: N
A35: Kommer Norge til å slippe inn 4 mål eller mer i gruppespillet? (J/N) | F35: J
A36: Kommer Norge til å møte Brasil i finalespillet? (J/N) | F36: N
A37: Hvem når lengst i VM av Norge og England? (Kryss av) | I37: Norge: | K37: England: | L37: x | M37: Like langt:
A38: Hvem blir Norges toppscorer? (Kryss av) | I38: Haaland: | J38: x | K38: Sørloth: | M38: En annen:
A40: Finalespillet:
A41: (2 poeng for hvert rett svar)
A42: Går Sverige videre fra gruppespillet? (J/N) | F42: J
A43: Hvor mange europeiske lag går til sekstendedelsfinale? | F43: 10
A44: Hvilke av vertsnasjonene går videre til åttendedelsfinale? | F44: USA, Mexico
...

Sheet Trude
A1: "Av alle uviktige ting i verden er fotball den aller viktigste" (pave Johannes Paul II)
A2: Gruppene:
A3: A: | B3: B: | C3: C: | E3: D: | F3: E: | K3: F: | N3: G: | S3: H: | Y3: I: | AC3: J: | AG3: K: | AK3: L:
A4: Mexico | B4: Canada | C4: Brasil | E4: USA | F4: Tyskland | K4: Nederland | N4: Belgia | S4: Spania | Y4: Frankrike | AC4: Argentina | AG4: Portugal | AK4: England
A5: Sør-Afrika | B5: Qatar | C5: Marokko | E5: Tyrkia | F5: Elfenbenskysten | K5: Japan | N5: Iran | S5: Saudi-Arabia | Y5: Norge | AC5: Østerrike | AG5: Usbekistan | AK5: Kroatia
A6: Sør-Korea | B6: Bosnia-Herceg. | C6: Haiti | E6: Australia | F6: Ecuador | K6: Sverige | N6: Egypt | S6: Uruguay | Y6: Irak | AC6: Jordan | AG6: Colombia | AK6: Panama
A7: Tsjekkia | B7: Sveits | C7: Skottland | E7: Paraguay | F7: Curacao | K7: Tunisia | N7: New Zealand | S7: Kapp Verde | Y7: Senegal | AC7: Algerie | AG7: DR Kongo | AK7: Ghana
A9: Gruppespillet:
A10: (Tipp sluttresultat i kampene. Rett resultat - H/U/B - gir 1 poeng, rett målscore gir 1 poeng)
A11: Gruppe A: Torsdag 11.06.2026 21:00 Mexico - Sør-Afrika | F11: 2 | G11: - | H11: 0
A12: Gruppe C: Søndag 14.06.2026 00:00 Brasil - Marokko | F12: 1 | G12: - | H12: 1
A13: Gruppe H: Mandag 15.06.2026 18:00 Spania - Kapp Verde | F13: 4 | G13: - | H13: 0
A14: Gruppe J: Tirsdag 17.06.2026 03:00 Argentina - Algerie | F14: 3 | G14: - | H14: 1
A15: Gruppe L: Onsdag 17.06.2026 22:00 England - Kroatia | F15: 1 | G15: - | H15: 1
A16: Gruppe F: Lørdag 20.06.2026 19:00 Nederland - Sverige | F16: 2 | G16: - | H16: 0
A17: Gruppe I: Tirsdag 23.06.2026 02:00 Norge - Senegal | F17: 2 | G17: - | H17: 0
A18: Gruppe E: Torsdag 25.06.2026 22:00 Ecuador - Tyskland | F18: 1 | G18: - | H18: 2
A19: Gruppe I: Fredag 26.06.2026 21:00 Norge - Frankrike | F19: 1 | G19: - | H19: 2
A20: Gruppe K: Lørdag 27.06.2026 02:00 Colombia - Portugal | F20: 1 | G20: - | H20: 3
A22: (Tipp sluttresultater i gruppene, 2 poeng for hvert rett svar)
A23: Hvem blir vinner i gruppe A? | C23: Mexico
A24: Hvem blir toer i gruppe B? | C24: Bosnia
A25: Går 3. plass i gruppe C videre? (J/N) | C25: N
A26: Hvem blir vinner i gruppe D? | C26: Tyrkia
A27: Hvem blir vinner i gruppe F? | C27: Nederland
A28: Hvem blir vinner i gruppe G? | C28: Egypt
A29: Hvem blir toer i gruppe I? | C29: Norge
A30: Går 3.plass i gruppe K videre? (J/N) | C30: N
A32: Norge:
A33: (2 poeng for hvert rett svar)
A34: Kommer Norge til å score 7 mål eller mer i gruppespillet? (J/N) | F34: N
A35: Kommer Norge til å slippe inn 4 mål eller mer i gruppespillet? (J/N) | F35: N
A36: Kommer Norge til å møte Brasil i finalespillet? (J/N) | F36: N
A37: Hvem når lengst i VM av Norge og England? (Kryss av) | I37: Norge: | K37: England: | L37: X | M37: Like langt:
A38: Hvem blir Norges toppscorer? (Kryss av) | I38: Haaland: | J38: X | K38: Sørloth: | M38: En annen:
A40: Finalespillet:
A41: (2 poeng for hvert rett svar)
A42: Går Sverige videre fra gruppespillet? (J/N) | F42: J
A43: Hvor mange europeiske lag går til sekstendedelsfinale? | F43: 11
A44: Hvilke av vertsnasjonene går videre til åttendedelsfinale? | F44: Ingen
...

Sheet Vidar
A1: "Av alle uviktige ting i verden er fotball den aller viktigste" (pave Johannes Paul II)
A2: Gruppene:
A3: A: | B3: B: | C3: C: | E3: D: | F3: E: | K3: F: | N3: G: | S3: H: | Y3: I: | AC3: J: | AG3: K: | AK3: L:
A4: Mexico | B4: Canada | C4: Brasil | E4: USA | F4: Tyskland | K4: Nederland | N4: Belgia | S4: Spania | Y4: Frankrike | AC4: Argentina | AG4: Portugal | AK4: England
A5: Sør-Afrika | B5: Qatar | C5: Marokko | E5: Tyrkia | F5: Elfenbenskysten | K5: Japan | N5: Iran | S5: Saudi-Arabia | Y5: Norge | AC5: Østerrike | AG5: Usbekistan | AK5: Kroatia
A6: Sør-Korea | B6: Bosnia-Herceg. | C6: Haiti | E6: Australia | F6: Ecuador | K6: Sverige | N6: Egypt | S6: Uruguay | Y6: Irak | AC6: Jordan | AG6: Colombia | AK6: Panama
A7: Tsjekkia | B7: Sveits | C7: Skottland | E7: Paraguay | F7: Curacao | K7: Tunisia | N7: New Zealand | S7: Kapp Verde | Y7: Senegal | AC7: Algerie | AG7: DR Kongo | AK7: Ghana
A9: Gruppespillet:
A10: (Tipp sluttresultat i kampene. Rett resultat - H/U/B - gir 1 poeng, rett målscore gir 1 poeng)
A11: Gruppe A: Torsdag 11.06.2026 21:00 Mexico - Sør-Afrika | F11: 2 | G11: - | H11: 1
A12: Gruppe C: Søndag 14.06.2026 00:00 Brasil - Marokko | F12: 1 | G12: - | H12: 0
A13: Gruppe H: Mandag 15.06.2026 18:00 Spania - Kapp Verde | F13: 2 | G13: - | H13: 1
A14: Gruppe J: Tirsdag 17.06.2026 03:00 Argentina - Algerie | F14: 3 | G14: - | H14: 1
A15: Gruppe L: Onsdag 17.06.2026 22:00 England - Kroatia | F15: 0 | G15: - | H15: 1
A16: Gruppe F: Lørdag 20.06.2026 19:00 Nederland - Sverige | F16: 3 | G16: - | H16: 1
A17: Gruppe I: Tirsdag 23.06.2026 02:00 Norge - Senegal | F17: 2 | G17: - | H17: 3
A18: Gruppe E: Torsdag 25.06.2026 22:00 Ecuador - Tyskland | F18: 0 | G18: - | H18: 3
A19: Gruppe I: Fredag 26.06.2026 21:00 Norge - Frankrike | F19: 2 | G19: - | H19: 3
A20: Gruppe K: Lørdag 27.06.2026 02:00 Colombia - Portugal | F20: 0 | G20: - | H20: 1
A22: (Tipp sluttresultater i gruppene, 2 poeng for hvert rett svar)
A23: Hvem blir vinner i gruppe A? | C23: Sør Korea
A24: Hvem blir toer i gruppe B? | C24: Bosnia-Herceg.
A25: Går 3. plass i gruppe C videre? (J/N) | C25: N
A26: Hvem blir vinner i gruppe D? | C26: Australia
A27: Hvem blir vinner i gruppe F? | C27: Nederland
A28: Hvem blir vinner i gruppe G? | C28: Iran
A29: Hvem blir toer i gruppe I? | C29: Senegal
A30: Går 3.plass i gruppe K videre? (J/N) | C30: N
A32: Norge:
A33: (2 poeng for hvert rett svar)
A34: Kommer Norge til å score 7 mål eller mer i gruppespillet? (J/N) | F34: N
A35: Kommer Norge til å slippe inn 4 mål eller mer i gruppespillet? (J/N) | F35: J
A36: Kommer Norge til å møte Brasil i finalespillet? (J/N) | F36: N
A37: Hvem når lengst i VM av Norge og England? (Kryss av) | I37: Norge: | K37: England: | L37: X | M37: Like langt:
A38: Hvem blir Norges toppscorer? (Kryss av) | I38: Haaland: | J38: X | K38: Sørloth: | M38: En annen:
A40: Finalespillet:
A41: (2 poeng for hvert rett svar)
A42: Går Sverige videre fra gruppespillet? (J/N) | F42: N
A43: Hvor mange europeiske lag går til sekstendedelsfinale? | F43: 9
A44: Hvilke av vertsnasjonene går videre til åttendedelsfinale? | F44: Mexico
...

Sheet Øystein
A1: "Av alle uviktige ting i verden er fotball den aller viktigste" (pave Johannes Paul II)
A2: Gruppene:
A3: A: | B3: B: | C3: C: | E3: D: | F3: E: | K3: F: | N3: G: | S3: H: | Y3: I: | AC3: J: | AG3: K: | AK3: L:
A4: Mexico | B4: Canada | C4: Brasil | E4: USA | F4: Tyskland | K4: Nederland | N4: Belgia | S4: Spania | Y4: Frankrike | AC4: Argentina | AG4: Portugal | AK4: England
A5: Sør-Afrika | B5: Qatar | C5: Marokko | E5: Tyrkia | F5: Elfenbenskysten | K5: Japan | N5: Iran | S5: Saudi-Arabia | Y5: Norge | AC5: Østerrike | AG5: Usbekistan | AK5: Kroatia
A6: Sør-Korea | B6: Bosnia-Herceg. | C6: Haiti | E6: Australia | F6: Ecuador | K6: Sverige | N6: Egypt | S6: Uruguay | Y6: Irak | AC6: Jordan | AG6: Colombia | AK6: Panama
A7: Tsjekkia | B7: Sveits | C7: Skottland | E7: Paraguay | F7: Curacao | K7: Tunisia | N7: New Zealand | S7: Kapp Verde | Y7: Senegal | AC7: Algerie | AG7: DR Kongo | AK7: Ghana
A9: Gruppespillet:
A10: (Tipp sluttresultat i kampene. Rett resultat - H/U/B - gir 1 poeng, rett målscore gir 1 poeng)
A11: Gruppe A: Torsdag 11.06.2026 21:00 Mexico - Sør-Afrika | F11: 3 | G11: - | H11: 1
A12: Gruppe C: Søndag 14.06.2026 00:00 Brasil - Marokko | F12: 0 | G12: - | H12: 0
A13: Gruppe H: Mandag 15.06.2026 18:00 Spania - Kapp Verde | F13: 4 | G13: - | H13: 0
A14: Gruppe J: Tirsdag 17.06.2026 03:00 Argentina - Algerie | F14: 1 | G14: - | H14: 0
A15: Gruppe L: Onsdag 17.06.2026 22:00 England - Kroatia | F15: 2 | G15: - | H15: 0
A16: Gruppe F: Lørdag 20.06.2026 19:00 Nederland - Sverige | F16: 1 | G16: - | H16: 1
A17: Gruppe I: Tirsdag 23.06.2026 02:00 Norge - Senegal | F17: 2 | G17: - | H17: 2
A18: Gruppe E: Torsdag 25.06.2026 22:00 Ecuador - Tyskland | F18: 1 | G18: - | H18: 2
A19: Gruppe I: Fredag 26.06.2026 21:00 Norge - Frankrike | F19: 0 | G19: - | H19: 3
A20: Gruppe K: Lørdag 27.06.2026 02:00 Colombia - Portugal | F20: 0 | G20: - | H20: 3
A22: (Tipp sluttresultater i gruppene, 2 poeng for hvert rett svar)
A23: Hvem blir vinner i gruppe A? | C23: Sør-Korea
A24: Hvem blir toer i gruppe B? | C24: Canada
A25: Går 3. plass i gruppe C videre? (J/N) | C25: N
A26: Hvem blir vinner i gruppe D? | C26: USA
A27: Hvem blir vinner i gruppe F? | C27: Nederland
A28: Hvem blir vinner i gruppe G? | C28: Belgia
A29: Hvem blir toer i gruppe I? | C29: Senegal
A30: Går 3.plass i gruppe K videre? (J/N) | C30: N
A32: Norge:
A33: (2 poeng for hvert rett svar)
A34: Kommer Norge til å score 7 mål eller mer i gruppespillet? (J/N) | F34: N
A35: Kommer Norge til å slippe inn 4 mål eller mer i gruppespillet? (J/N) | F35: J
A36: Kommer Norge til å møte Brasil i finalespillet? (J/N) | F36: J
A37: Hvem når lengst i VM av Norge og England? (Kryss av) | I37: Norge: | K37: England: | L37: X | M37: Like langt:
A38: Hvem blir Norges toppscorer? (Kryss av) | I38: Haaland: | K38: Sørloth: | L38: X | M38: En annen:
A40: Finalespillet:
A41: (2 poeng for hvert rett svar)
A42: Går Sverige videre fra gruppespillet? (J/N) | F42: J
A43: Hvor mange europeiske lag går til sekstendedelsfinale? | F43: 8
A44: Hvilke av vertsnasjonene går videre til åttendedelsfinale? | F44: USA
...

Sheet Ådne
A1: "Av alle uviktige ting i verden er fotball den aller viktigste" (pave Johannes Paul II)
A2: Gruppene:
A3: A: | B3: B: | C3: C: | E3: D: | F3: E: | K3: F: | N3: G: | S3: H: | Y3: I: | AC3: J: | AG3: K: | AK3: L:
A4: Mexico | B4: Canada | C4: Brasil | E4: USA | F4: Tyskland | K4: Nederland | N4: Belgia | S4: Spania | Y4: Frankrike | AC4: Argentina | AG4: Portugal | AK4: England
A5: Sør-Afrika | B5: Qatar | C5: Marokko | E5: Tyrkia | F5: Elfenbenskysten | K5: Japan | N5: Iran | S5: Saudi-Arabia | Y5: Norge | AC5: Østerrike | AG5: Usbekistan | AK5: Kroatia
A6: Sør-Korea | B6: Bosnia-Herceg. | C6: Haiti | E6: Australia | F6: Ecuador | K6: Sverige | N6: Egypt | S6: Uruguay | Y6: Irak | AC6: Jordan | AG6: Colombia | AK6: Panama
A7: Tsjekkia | B7: Sveits | C7: Skottland | E7: Paraguay | F7: Curacao | K7: Tunisia | N7: New Zealand | S7: Kapp Verde | Y7: Senegal | AC7: Algerie | AG7: DR Kongo | AK7: Ghana
A9: Gruppespillet:
A10: (Tipp sluttresultat i kampene. Rett resultat - H/U/B - gir 1 poeng, rett målscore gir 1 poeng)
A11: Gruppe A: Torsdag 11.06.2026 21:00 Mexico - Sør-Afrika | F11: 2 | G11: - | H11: 1
A12: Gruppe C: Søndag 14.06.2026 00:00 Brasil - Marokko | F12: 2 | G12: - | H12: 1
A13: Gruppe H: Mandag 15.06.2026 18:00 Spania - Kapp Verde | F13: 3 | G13: - | H13: 0
A14: Gruppe J: Tirsdag 17.06.2026 03:00 Argentina - Algerie | F14: 2 | G14: - | H14: 1
A15: Gruppe L: Onsdag 17.06.2026 22:00 England - Kroatia | F15: 2 | G15: - | H15: 1
A16: Gruppe F: Lørdag 20.06.2026 19:00 Nederland - Sverige | F16: 3 | G16: - | H16: 1
A17: Gruppe I: Tirsdag 23.06.2026 02:00 Norge - Senegal | F17: 2 | G17: - | H17: 1
A18: Gruppe E: Torsdag 25.06.2026 22:00 Ecuador - Tyskland | F18: 1 | G18: - | H18: 3
A19: Gruppe I: Fredag 26.06.2026 21:00 Norge - Frankrike | F19: 1 | G19: - | H19: 3
A20: Gruppe K: Lørdag 27.06.2026 02:00 Colombia - Portugal | F20: 2 | G20: - | H20: 3
A22: (Tipp sluttresultater i gruppene, 2 poeng for hvert rett svar)
A23: Hvem blir vinner i gruppe A? | C23: Mexico
A24: Hvem blir toer i gruppe B? | C24: Canada
A25: Går 3. plass i gruppe C videre? (J/N) | C25: N
A26: Hvem blir vinner i gruppe D? | C26: USA
A27: Hvem blir vinner i gruppe F? | C27: Nederland
A28: Hvem blir vinner i gruppe G? | C28: Belgia
A29: Hvem blir toer i gruppe I? | C29: Norge
A30: Går 3.plass i gruppe K videre? (J/N) | C30: N
A32: Norge:
A33: (2 poeng for hvert rett svar)
A34: Kommer Norge til å score 7 mål eller mer i gruppespillet? (J/N) | F34: N
A35: Kommer Norge til å slippe inn 4 mål eller mer i gruppespillet? (J/N) | F35: J
A36: Kommer Norge til å møte Brasil i finalespillet? (J/N) | F36: N
A37: Hvem når lengst i VM av Norge og England? (Kryss av) | I37: Norge: | K37: England: | L37: X | M37: Like langt:
A38: Hvem blir Norges toppscorer? (Kryss av) | I38: Haaland: | J38: X | K38: Sørloth: | M38: En annen:
A40: Finalespillet:
A41: (2 poeng for hvert rett svar)
A42: Går Sverige videre fra gruppespillet? (J/N) | F42: N
A43: Hvor mange europeiske lag går til sekstendedelsfinale? | F43: 10
A44: Hvilke av vertsnasjonene går videre til åttendedelsfinale? | F44: Mexico
...

Sheet Data
A1: Navn | B1: Mexico-Sør-Afrika (H) | C1: Mexico-Sør-Afrika (B) | D1: Brasil-Marokko (H) | E1: Brasil-Marokko (B) | F1: Spania-Kapp Verde (H) | G1: Spania-Kapp Verde (B) | H1: Argentina-Algerie (H) | I1: Argentina-Algerie (B) | J1: England-Kroatia (H) | K1: England-Kroatia (B) | L1: Nederland-Sverige (H) | M1: Nederland-Sverige (B) | N1: Norge-Senegal (H) | O1: Norge-Senegal (B) | P1: Ecuador-Tyskland (H) | Q1: Ecuador-Tyskland (B) | R1: Norge-Frankrike (H) | S1: Norge-Frankrike (B) | T1: Colombia-Portugal (H) | U1: Colombia-Portugal (B) | V1: Res 1 | W1: Res 2 | X1: Res 3 | Y1: Res 4 | Z1: Res 5 | AA1: Res 6 | AB1: Res 7 | AC1: Res 8 | AD1: Res 9 | AE1: Res 10 | AF1: A-vinner | AG1: B-toer | AH1: C 3.pl videre | AI1: D-vinner | AJ1: F-vinner | AK1: G-vinner | AL1: I-toer | AM1: K 3.pl videre | AN1: Norge 7+ mål | AO1: Norge innslipp 4+ | AP1: Norge møter Brasil | AQ1: Lengst N/Eng | AR1: Toppscorer
A2: Ahilan | B2: =Ahilan!F11 -> 2 | C2: =Ahilan!H11 -> 0 | D2: =Ahilan!F12 -> 1 | E2: =Ahilan!H12 -> 0 | F2: =Ahilan!F13 -> 3 | G2: =Ahilan!H13 -> 0 | H2: =Ahilan!F14 -> 2 | I2: =Ahilan!H14 -> 1 | J2: =Ahilan!F15 -> 0 | K2: =Ahilan!H15 -> 0 | L2: =Ahilan!F16 -> 2 | M2: =Ahilan!H16 -> 1 | N2: =Ahilan!F17 -> 0 | O2: =Ahilan!H17 -> 0 | P2: =Ahilan!F18 -> 0 | Q2: =Ahilan!H18 -> 1 | R2: =Ahilan!F19 -> 0 | S2: =Ahilan!H19 -> 1 | T2: =Ahilan!F20 -> 2 | U2: =Ahilan!H20 -> 3 | V2: =IF(B2>C2,"H",IF(B2<C2,"B","U")) -> H | W2: =IF(D2>E2,"H",IF(D2<E2,"B","U")) -> H | X2: =IF(F2>G2,"H",IF(F2<G2,"B","U")) -> H | Y2: =IF(H2>I2,"H",IF(H2<I2,"B","U")) -> H | Z2: =IF(J2>K2,"H",IF(J2<K2,"B","U")) -> U | AA2: =IF(L2>M2,"H",IF(L2<M2,"B","U")) -> H | AB2: =IF(N2>O2,"H",IF(N2<O2,"B","U")) -> U | AC2: =IF(P2>Q2,"H",IF(P2<Q2,"B","U")) -> B | AD2: =IF(R2>S2,"H",IF(R2<S2,"B","U")) -> B | AE2: =IF(T2>U2,"H",IF(T2<U2,"B","U")) -> B | AF2: =Ahilan!C23 -> Tsjekkia | AG2: =Ahilan!C24 -> Sveits | AH2: =IF(LOWER(LEFT(TRIM(Ahilan!C25),1))="j","Ja","Nei") -> Nei | AI2: =Ahilan!C26 -> Tyrkia | AJ2: =Ahilan!C27 -> Nederland | AK2: =Ahilan!C28 -> Belgia | AL2: =Ahilan!C29 -> Senegal | AM2: =IF(LOWER(LEFT(TRIM(Ahilan!C30),1))="j","Ja","Nei") -> Nei | AN2: =IF(LOWER(LEFT(TRIM(Ahilan!F34),1))="j","Ja","Nei") -> Nei | AO2: =IF(LOWER(LEFT(TRIM(Ahilan!F35),1))="j","Ja","Nei") -> Nei | AP2: =IF(LOWER(LEFT(TRIM(Ahilan!F36),1))="j","Ja","Nei") -> Nei | AQ2: =IF(TRIM(Ahilan!J37)<>"","Norge",IF(TRIM(Ahilan!L37)<>"","England",IF(TRIM(Ahilan!N37)<>"","Like langt","-"))) -> England | AR2: =IF(TRIM(Ahilan!J38)<>"","Haaland",IF(TRIM(Ahilan!L38)<>"","Sørloth",IF(TRIM(Ahilan!N38)<>"","En annen","-"))) -> Haaland
